<?xml version="1.0"?>

<robot xmlns:xacro="http://ros.org/wiki/xacro">

    <xacro:macro name="wheel_macro" params="parent prefix xyz r">

        <!-- joint -->
        <joint name="${prefix}_joint" type="continuous">
            <origin xyz="${xyz}" rpy="${radians(-90)} 0 0"/>
            <parent link="${parent}"/>
            <child  link="${prefix}_link"/>
            <axis xyz="0 0 1" />
        </joint>

        <!-- link -->
        <link name="${prefix}_link">
            <inertial>
                <origin xyz="0 0 0" rpy="0 0 0"/>
                <mass value="0.1"/>
                <inertia ixx="0.0001" ixy="0.0" ixz="0.0" iyy="0.0001" iyz="0.0" izz="0.0001"/>
            </inertial>
            <visual>
                <geometry>
                    <cylinder radius="${r}" length="0.02" />
                </geometry>
                <material name="red"/>
            </visual>
            <collision>
                <geometry>
                    <cylinder radius="${r}" length="0.02" />
                </geometry>
            </collision>
        </link>

        <gazebo reference="${prefix}_link">
          <material>Gazebo/Red</material>
        </gazebo>

    </xacro:macro>


</robot>
