<?xml version="1.0"?>

<robot xmlns:xacro="http://ros.org/wiki/xacro">

    <xacro:macro name="wheel_macro" params="parent prefix xyz r">

        <!-- joint -->
        <joint name="${prefix}_joint" type="continuous">
            <origin xyz="${xyz}" rpy="${radians(-90)} 0 0"/>
            <parent link="${parent}"/>
            <child  link="${prefix}_link"/>
            <axis xyz="0 0 1" />
            <limit velocity="12.0" effort="0.4" />
            <dynamics damping="0.1"/>
        </joint>

        <!-- transimission -->
        <transmission name="${prefix}_trans" type="SimpleTransmission">
            <type>transmission_interface/SimpleTransmission</type>
            <actuator name="${prefix}_motor">
                <mechanicalReduction>1</mechanicalReduction>
            </actuator>
            <joint name="${prefix}_joint">
                <hardwareInterface>hardware_interface/VelocityJointInterface</hardwareInterface>
            </joint>
        </transmission>

        <!-- link -->
        <link name="${prefix}_link">
            <inertial>
                <origin xyz="0 0 0" rpy="0 0 0"/>
                <mass value="0.1"/>
                <inertia ixx="0.0001" ixy="0.0" ixz="0.0" iyy="0.0001" iyz="0.0" izz="0.0001"/>
            </inertial>
            <visual>
                <geometry>
                    <cylinder radius="${r}" length="0.02" />
                </geometry>
                <material name="red"/>
            </visual>
            <collision>
                <geometry>
                    <cylinder radius="${r}" length="0.02" />
                </geometry>
            </collision>
        </link>

        <gazebo reference="${prefix}_link">
            <material>Gazebo/Red</material>
            <material>Gazebo/Red</material>
            <mu1 value="2.5" />
            <mu2 value="2.5" />
            <kp value="50000" />
            <kd value="10" />
        </gazebo>

    </xacro:macro>


</robot>
